[2025-08-19T09:07:39.092+0000] {task_context_logger.py:104} ERROR - Executor reports task instance <TaskInstance: data_audit_dag.validate_audit_task manual__2025-08-19T09:05:52.580030+00:00 [queued]> finished (failed) although the task says it's queued. (Info: None) Was the task killed externally?
