[2025-08-19T09:49:00.935+0000] {local_task_job_runner.py:120} INFO - ::group::Pre task execution logs
[2025-08-19T09:49:00.965+0000] {taskinstance.py:2076} INFO - Dependencies all met for dep_context=non-requeueable deps ti=<TaskInstance: data_audit_dag.validate_audit_task manual__2025-08-19T09:48:55.573414+00:00 [queued]>
[2025-08-19T09:49:00.977+0000] {taskinstance.py:2076} INFO - Dependencies all met for dep_context=requeueable deps ti=<TaskInstance: data_audit_dag.validate_audit_task manual__2025-08-19T09:48:55.573414+00:00 [queued]>
[2025-08-19T09:49:00.982+0000] {taskinstance.py:2306} INFO - Starting attempt 1 of 2
[2025-08-19T09:49:01.006+0000] {taskinstance.py:2330} INFO - Executing <Task(PythonOperator): validate_audit_task> on 2025-08-19 09:48:55.573414+00:00
[2025-08-19T09:49:01.018+0000] {warnings.py:110} WARNING - /home/***/.local/lib/python3.12/site-packages/***/task/task_runner/standard_task_runner.py:61: DeprecationWarning: This process (pid=93) is multi-threaded, use of fork() may lead to deadlocks in the child.
  pid = os.fork()

[2025-08-19T09:49:01.021+0000] {standard_task_runner.py:63} INFO - Started process 95 to run task
[2025-08-19T09:49:01.021+0000] {standard_task_runner.py:90} INFO - Running: ['***', 'tasks', 'run', 'data_audit_dag', 'validate_audit_task', 'manual__2025-08-19T09:48:55.573414+00:00', '--job-id', '42', '--raw', '--subdir', 'DAGS_FOLDER/Assessment_2/data_audit_dag.py', '--cfg-path', '/tmp/tmpagnpvqz1']
[2025-08-19T09:49:01.024+0000] {standard_task_runner.py:91} INFO - Job 42: Subtask validate_audit_task
[2025-08-19T09:49:01.132+0000] {task_command.py:426} INFO - Running <TaskInstance: data_audit_dag.validate_audit_task manual__2025-08-19T09:48:55.573414+00:00 [running]> on host 37fc8edea13d
[2025-08-19T09:49:01.270+0000] {taskinstance.py:2648} INFO - Exporting env vars: AIRFLOW_CTX_DAG_EMAIL='youremail@example.com' AIRFLOW_CTX_DAG_OWNER='rajpriya' AIRFLOW_CTX_DAG_ID='data_audit_dag' AIRFLOW_CTX_TASK_ID='validate_audit_task' AIRFLOW_CTX_EXECUTION_DATE='2025-08-19T09:48:55.573414+00:00' AIRFLOW_CTX_TRY_NUMBER='1' AIRFLOW_CTX_DAG_RUN_ID='manual__2025-08-19T09:48:55.573414+00:00'
[2025-08-19T09:49:01.273+0000] {taskinstance.py:430} INFO - ::endgroup::
[2025-08-19T09:49:01.292+0000] {logging_mixin.py:188} INFO - [Audit] Validation result saved: {'data': {'user_id': 101, 'balance': 141, 'timestamp': '2025-08-19 09:48:58.757627'}, 'valid': False}
[2025-08-19T09:49:01.293+0000] {taskinstance.py:441} INFO - ::group::Post task execution logs
[2025-08-19T09:49:01.294+0000] {taskinstance.py:2905} ERROR - Task failed with exception
Traceback (most recent call last):
  File "/home/airflow/.local/lib/python3.12/site-packages/airflow/models/taskinstance.py", line 465, in _execute_task
    result = _execute_callable(context=context, **execute_callable_kwargs)
             ^^^^^^^^^^^^^^^^^^^^^^^^^^^^^^^^^^^^^^^^^^^^^^^^^^^^^^^^^^^^^
  File "/home/airflow/.local/lib/python3.12/site-packages/airflow/models/taskinstance.py", line 432, in _execute_callable
    return execute_callable(context=context, **execute_callable_kwargs)
           ^^^^^^^^^^^^^^^^^^^^^^^^^^^^^^^^^^^^^^^^^^^^^^^^^^^^^^^^^^^^
  File "/home/airflow/.local/lib/python3.12/site-packages/airflow/models/baseoperator.py", line 400, in wrapper
    return func(self, *args, **kwargs)
           ^^^^^^^^^^^^^^^^^^^^^^^^^^^
  File "/home/airflow/.local/lib/python3.12/site-packages/airflow/operators/python.py", line 235, in execute
    return_value = self.execute_callable()
                   ^^^^^^^^^^^^^^^^^^^^^^^
  File "/home/airflow/.local/lib/python3.12/site-packages/airflow/operators/python.py", line 252, in execute_callable
    return self.python_callable(*self.op_args, **self.op_kwargs)
           ^^^^^^^^^^^^^^^^^^^^^^^^^^^^^^^^^^^^^^^^^^^^^^^^^^^^^
  File "/opt/airflow/dags/Assessment_2/data_audit_dag.py", line 42, in audit_rule
    raise ValueError("Audit failed: balance below threshold!")
ValueError: Audit failed: balance below threshold!
[2025-08-19T09:49:01.316+0000] {taskinstance.py:1206} INFO - Marking task as UP_FOR_RETRY. dag_id=data_audit_dag, task_id=validate_audit_task, run_id=manual__2025-08-19T09:48:55.573414+00:00, execution_date=20250819T094855, start_date=20250819T094900, end_date=20250819T094901
[2025-08-19T09:49:01.339+0000] {standard_task_runner.py:110} ERROR - Failed to execute job 42 for task validate_audit_task (Audit failed: balance below threshold!; 95)
[2025-08-19T09:49:01.398+0000] {local_task_job_runner.py:240} INFO - Task exited with return code 1
[2025-08-19T09:49:01.429+0000] {taskinstance.py:3498} INFO - 0 downstream tasks scheduled from follow-on schedule check
[2025-08-19T09:49:01.434+0000] {local_task_job_runner.py:222} INFO - ::endgroup::
