[2025-08-19T09:42:54.982+0000] {task_context_logger.py:104} ERROR - Executor reports task instance <TaskInstance: data_audit_dag.final_status_task manual__2025-08-19T09:22:15.873297+00:00 [queued]> finished (failed) although the task says it's queued. (Info: None) Was the task killed externally?
